import { render, screen, fireEvent } from "@testing-library/react";
import { describe, it, expect, vi, beforeEach, afterEach } from "vitest";
import { ErrorBoundary } from "@/components/ErrorBoundary";

const ThrowError = () => {
  throw new Error("Test error");
};

describe("ErrorBoundary", () => {
  beforeEach(() => {
    vi.spyOn(console, "error").mockImplementation(() => {});
  });

  afterEach(() => {
    vi.restoreAllMocks();
  });

  it("renders children when there is no error", () => {
    render(
      <ErrorBoundary>
        <div>Test content</div>
      </ErrorBoundary>
    );

    expect(screen.getByText("Test content")).toBeInTheDocument();
  });

  it("renders error message when child component throws", () => {
    render(
      <ErrorBoundary>
        <ThrowError />
      </ErrorBoundary>
    );

    expect(screen.getByText("Something went wrong")).toBeInTheDocument();
    expect(screen.getByText("Test error")).toBeInTheDocument();
    expect(screen.getByText("Try again")).toBeInTheDocument();
  });

  it("renders custom fallback when provided", () => {
    const customFallback = <div>Custom error message</div>;

    render(
      <ErrorBoundary fallback={customFallback}>
        <ThrowError />
      </ErrorBoundary>
    );

    expect(screen.getByText("Custom error message")).toBeInTheDocument();
    expect(screen.queryByText("Something went wrong")).not.toBeInTheDocument();
  });

  it("calls window.location.reload when Try again is clicked", () => {
    const reload = vi.fn();
    Object.defineProperty(window, "location", {
      value: { reload },
      writable: true,
    });

    render(
      <ErrorBoundary>
        <ThrowError />
      </ErrorBoundary>
    );

    fireEvent.click(screen.getByText("Try again"));
    expect(reload).toHaveBeenCalled();
  });
});
